Workbook

Sheet Start Here
A1: - | B1: In The Black — Premium Toolkit
B3: Your all-in-one personal finance system. Start with your Budget Input, then the Debt Payoff, Net Worth, Emergency Fund, and lastly Annual Review. Feedback and Unified Dashboard tabs work together automatically. The Interest Saved and Mortgage Estimator are tools to utilize when you want to either evaluate debt payment numbers or purchase a home.
B6: START HERE | QUICK SETUP
B7: # | C7: Task | D7: Done? | E7: Notes
B8: 1 | C8: Fill out the Budget Input tab. You do not need to input anything into the "TOTALS" table. That will update automatically. Review the Feedback page to see your starting point.
B9: 2 | C9: Add your debts on the Debt Payoff tab. Include every debt you currently have. You can use the Interest Saved tab to figure out how much quicker you could pay off a particular debt!
B10: 3 | C10: Enter your assets and liabilities on the Net Worth tab.
B11: 4 | C11: Set and evaluate your Emergency Fund target and current balance.
B12: 5 | C12: Log this year's numbers on the Annual Review tab, or start tracking monthly numbers moving forward!
B13: 6 | C13: Revisit as much as you would like and watch your score, cash flow, debt, and net worth trend.
B15: LEGEND & INPUT GUIDE
C16: Yellow cells — Edit these cells with your own numbers.
C17: Blue cells — Benchmark numbers; edit these cells.
C18: Green rows — Income.
C19: Red rows — Expenses.
C20: Gray rows — Taxes.
C21: Purple rows — Investing.
C22: Light Yellow — Subscriptions.
B23: Black | C23: Black text — Automatic calculations; avoid typing over formulas.
B24: Green | C24: Green text — Pulled automatically from another tab.
B26: A NOTE ON THE GUIDANCE
B27: This toolkit uses common personal-finance rules of thumb (for example, keeping housing costs around 30% of income) to provide an educational read on your finances. It is NOT personalized financial advice. Every household is different, and the benchmark assumptions can be adjusted to fit your situation. Use this workbook to identify patterns, find the source of issues, compare results against benchmarks you choose, and build a financial system that works for you.
B30: TIPS
B31: Change your numbers in the source tabs — the Unified Dashboard updates automatically.
B32: Automatic calculation cells are designed to update themselves. They are also designed to be protected. If you customize the workbook, make a copy first so you always have a clean master version.
B33: The point of this spreadsheet is to serve you. To put you in charge of your finances and keep you in charge. Feel free to change things about this sheet if it helps you understand things more, or cosmetically fits you better. If you are having trouble changing things to be the way you want them to be, reach out and we'll be happy to help!
B34: The more honest you are with yourself about the inputs in this workbook, the better and faster this product will help you reach your goals.
B35: This workbook comes preloaded with example numbers so you can see how the system works together. Replace the example inputs with your own information before relying on the results—especially on Budget Input tab, where example values can otherwise affect your totals.
B37: In The Black — Premium Toolkit Version 1.0

Sheet Unified Dashboard
B1: Unified Dashboard | M1: Financial Health Score
B2: Do not edit this tab. This dashboard is fully live — every figure pulls automatically from the Budget Input, Debt Payoff, Net Worth, and Emergency Fund tabs. Change any editable input on the other tabs and the numbers, status badges, and charts refresh instantly.
M3: SUB-SCORES (0–100)
B4: BUDGET | E4: DEBT | H4: NET WORTH | M4: Savings Rate | N4: =ROUND(IFERROR(MAX(0,MIN('Budget Input'!$I$9/'Budget Input'!$I$5/0.2*100,100)),0),0) -> 100
B5: Monthly Income | C5: ='Budget Input'!I5 -> 7000 | E5: Total Debt Balance | F5: ='Debt Payoff'!M4 -> 18000 | H5: Total Assets | I5: ='Net Worth'!C11 -> 137000 | M5: Debt-to-Income | N5: =ROUND(IF('Budget Input'!$I$5=0,IF('Debt Payoff'!$M$7>0,0,100),MAX(0,MIN(100-('Debt Payoff'!$M$7/'Budget Input'!$I$5)/0.36*100,100))),0) -> 86
B6: Monthly Expenses | C6: ='Budget Input'!I6 -> 3250 | E6: Total Monthly Debt Payment | F6: ='Debt Payoff'!M7 -> 350 | H6: Total Liabilities | I6: ='Net Worth'!C19 -> 18000 | M6: Emergency Fund | N6: =ROUND(IFERROR(MAX(0,MIN('Emergency Fund'!$C$11/6*100,100)),0),0) -> 48
B7: Monthly Taxes | C7: ='Budget Input'!I8 -> 1700 | H7: Emergency Fund Balance | I7: ='Emergency Fund'!C6 -> 10000 | M7: Spending Discipline | N7: =ROUND(IF('Budget Input'!$I$5=0,IF('Budget Input'!$I$6>0,0,100),MAX(0,MIN(100-('Budget Input'!$I$6/'Budget Input'!$I$5-0.5)*200,100))),0) -> 100
B8: Monthly Subscriptions | C8: ='Budget Input'!I10 -> 20.333333
M9: YOUR SCORE
B10: UNIFIED METRICS | M10: Financial Health Score | N10: =ROUND(AVERAGE(N4:N7),0) -> 84
B11: NET WORTH | E11: MONTHLY CASH FLOW | H11: FINANCIAL HEALTH SCORE | K11: Chart Data | M11: Grade | N11: =IF(N10>=90,"A",IF(N10>=80,"B",IF(N10>=70,"C",IF(N10>=60,"D","F")))) -> B
B12: ='Net Worth'!C22 -> 119000 | E12: ='Budget Input'!I11 -> 79.666667 | H12: =N10 -> 84 | M12: What this means | N12: =IF(N10>=90,"Excellent — your finances are in great shape. Keep it up.",IF(N10>=80,"Strong financial health with a few areas to refine.",IF(N10>=70,"You're on the right track — focus on your lowest sub-score to climb higher.",IF(N10>=60,"A few structural issues are holding your finances back — prioritize the lowest sub-score.","Your finances need attention. Start with the lowest sub-score and build from there.")))) -> Strong financial health with a few areas to refine.
B13: =IF(B12>=0,"Positive","Negative") -> Positive | E13: =IF(E12>=0,"Surplus","Deficit") -> Surplus | H13: =IF(H12>=80,"Strong",IF(H12>=70,"Fair",IF(H12>=60,"Getting there","Needs work"))) -> Strong | K13: Expenses | L13: ='Budget Input'!I6 -> 3250
B14: DEBT-TO-INCOME | E14: SAVINGS RATE | H14: EMERGENCY FUND | K14: Debt Payments | L14: ='Debt Payoff'!M7 -> 350
B15: =IFERROR(F6/C5,0) -> 0.05 | E15: =IFERROR('Budget Input'!I9/'Budget Input'!I5,0) -> 0.22857143 | H15: ='Emergency Fund'!C11 -> 2.8571429 | K15: Savings/Investing | L15: ='Budget Input'!I9 -> 1600
B16: =IF(B15<=0.36,"On target","Above target") -> On target | E16: =IF(E15>=0.2,"On target","Below target") -> On target | H16: =IF(H15>=6,"Fully funded","Building") -> Building | K16: Leftover | L16: ='Budget Input'!I11 -> 79.666667
K19: Assets | L19: ='Net Worth'!C11 -> 137000
K20: Liabilities | L20: ='Net Worth'!C12

Sheet Budget Input
B1: Monthly Budget Inputs
B4: INPUT | C4: CATEGORY | D4: MONTHLY PAYMENT | E4: PAYMENT METHOD | F4: NOTES | H4: TOTALS
B5: Income | C5: Salary/Wages | D5: 7000 | E5: Bank | H5: Monthly Income | I5: =SUMIF($B$5:$B$39,"Income",$D$5:$D$39) -> 7000
B6: Expense | C6: Housing | D6: 1900 | E6: Bank | H6: Monthly Expenses | I6: =SUMIF($B$5:$B$39,"Expense",$D$5:$D$39) -> 3250
B7: Expense | C7: Transportation | D7: 300 | E7: Credit Card | F7: Gas + Bus Pass | H7: Monthly Debt | I7: ='Debt Payoff'!M7 -> 350
B8: Expense | C8: Food | D8: 300 | E8: Credit Card | H8: Monthly Taxes | I8: =SUMIF($B$5:$B$39,"Taxes",$D$5:$D$39) -> 1700
B9: Expense | C9: Utilities | D9: 400 | E9: Bank | F9: Water + Electric | H9: Monthly Investing | I9: =SUMIF($B$5:$B$39,"Investing",$D$5:$D$39) -> 1600
B10: Expense | C10: Insurance | D10: 250 | E10: Bank | F10: Auto + Renters | H10: Monthly Subscriptions | I10: =SUMPRODUCT(($B$43:$B$67="Subscription")*($E$43:$E$67)*(($G$43:$G$67="Annual")/12+($G$43:$G$67<>"Annual"))) -> 20.333333
B11: Expense | C11: Personal & Discretionary | D11: 100 | E11: Credit Card | H11: Monthly Surplus | I11: =I5-I6-I7-I8-I9-I10 -> 79.666667
B12: Taxes | C12: Federal | D12: 1000 | H12: Monthly Investing Rate | I12: =IFERROR(I9/I5,0) -> 0.22857143
B13: Taxes | C13: State | D13: 500
B14: Taxes | C14: Social Security | D14: 200 | H14: Don't input your debt payments on this tab. Input them on the Debt Payoff tab. Monthly Debt is still shown here for your reference.
B15: Investing | C15: 401(k) | D15: 1000
B16: Investing | C16: College Fund | D16: 300
B17: Investing | C17: Emergency Fund | D17: 300
B41: SUBSCRIPTIONS DETAIL (optional — helps track each individual service)
B42: TYPE | C42: SERVICE | D42: PAYMENT METHOD | E42: ACTUAL PAID | F42: ORIGINAL PRICE | G42: FREQUENCY | H42: CANCEL?
B43: Subscription | C43: Spotify | D43: Credit Card | E43: 12 | F43: 12 | G43: Monthly | H43: No
B44: Subscription | C44: Uber One | D44: Credit Card | E44: 100 | F44: 100 | G44: Annual | H44: Yes
B45: Subscription | C45: Apple Music | D45: Credit Card | E45: 0 | F45: 12 | G45: Monthly | H45: No
B46: Subscription
B47: Subscription
B48: Subscription
B49: Subscription
B50: Subscription
B51: Subscription
B52: Subscription
B53: Subscription
B54: Subscription
B55: Subscription
B56: Subscription
B57: Subscription
... B71: Tip: Original Price must be filled out for the appropriate subscription for the subscription count on the Feedback tab to correctly compute.

Sheet Feedback
B1: Your Budget Dashboard & Feedback
B3: SUMMARY
B4: Total Monthly Income | C4: =+'Budget Input'!I5 -> 7000
B5: Total Monthly Expenses | C5: =+'Budget Input'!I6 -> 3250
B6: Monthly Surplus / Deficit | C6: =+'Budget Input'!I11 -> 79.666667
B7: Investing Rate (Investing ÷ Income) | C7: =+'Budget Input'!I12 -> 0.22857143
B9: EXPENSE BREAKDOWN vs. RECOMMENDED GUIDELINES
B10: Category | C10: Monthly Amount | D10: % of Income | E10: Benchmark | F10: Direction | G10: Status
B11: Housing | C11: =SUMIFS('Budget Input'!$D$5:$D$39,'Budget Input'!$B$5:$B$39,"Expense",'Budget Input'!$C$5:$C$39,B11) -> 1900 | D11: =IFERROR(C11/$C$4,0) -> 0.27142857 | E11: 0.3 | F11: Max | G11: =IF(E11="","—",IF(F11="Max",IF(D11<=E11,"OK - within recommended range","Above recommended - consider reducing"),IF(D11>=E11,"OK - meeting target","Below recommended - consider increasing"))) -> OK - within recommended range
B12: Transportation | C12: =SUMIFS('Budget Input'!$D$5:$D$39,'Budget Input'!$B$5:$B$39,"Expense",'Budget Input'!$C$5:$C$39,B12) -> 300 | D12: =IFERROR(C12/$C$4,0) -> 0.042857143 | E12: 0.15 | F12: Max | G12: =IF(E12="","—",IF(F12="Max",IF(D12<=E12,"OK - within recommended range","Above recommended - consider reducing"),IF(D12>=E12,"OK - meeting target","Below recommended - consider increasing"))) -> OK - within recommended range
B13: Food | C13: =SUMIFS('Budget Input'!$D$5:$D$39,'Budget Input'!$B$5:$B$39,"Expense",'Budget Input'!$C$5:$C$39,B13) -> 300 | D13: =IFERROR(C13/$C$4,0) -> 0.042857143 | E13: 0.15 | F13: Max | G13: =IF(E13="","—",IF(F13="Max",IF(D13<=E13,"OK - within recommended range","Above recommended - consider reducing"),IF(D13>=E13,"OK - meeting target","Below recommended - consider increasing"))) -> OK - within recommended range
B14: Utilities | C14: =SUMIFS('Budget Input'!$D$5:$D$39,'Budget Input'!$B$5:$B$39,"Expense",'Budget Input'!$C$5:$C$39,B14) -> 400 | D14: =IFERROR(C14/$C$4,0) -> 0.057142857 | E14: 0.1 | F14: Max | G14: =IF(E14="","—",IF(F14="Max",IF(D14<=E14,"OK - within recommended range","Above recommended - consider reducing"),IF(D14>=E14,"OK - meeting target","Below recommended - consider increasing"))) -> OK - within recommended range
B15: Insurance | C15: =SUMIFS('Budget Input'!$D$5:$D$39,'Budget Input'!$B$5:$B$39,"Expense",'Budget Input'!$C$5:$C$39,B15) -> 250 | D15: =IFERROR(C15/$C$4,0) -> 0.035714286 | E15: 0.1 | F15: Max | G15: =IF(E15="","—",IF(F15="Max",IF(D15<=E15,"OK - within recommended range","Above recommended - consider reducing"),IF(D15>=E15,"OK - meeting target","Below recommended - consider increasing"))) -> OK - within recommended range
B16: Debt Payments | C16: ='Debt Payoff'!M7 -> 350 | D16: =IFERROR(C16/$C$4,0) -> 0.05 | E16: 0.15 | F16: Max | G16: =IF(E16="","—",IF(F16="Max",IF(D16<=E16,"OK - within recommended range","Above recommended - consider reducing"),IF(D16>=E16,"OK - meeting target","Below recommended - consider increasing"))) -> OK - within recommended range
B17: Subscriptions | C17: =+'Budget Input'!I10 -> 20.333333 | D17: =IFERROR(C17/$C$4,0) -> 0.0029047619 | E17: 0.05 | F17: Max | G17: =IF(E17="","—",IF(F17="Max",IF(D17<=E17,"OK - within recommended range","Above recommended - consider reducing"),IF(D17>=E17,"OK - meeting target","Below recommended - consider increasing"))) -> OK - within recommended range
B18: Personal & Discretionary | C18: =SUMIFS('Budget Input'!$D$5:$D$39,'Budget Input'!$B$5:$B$39,"Expense",'Budget Input'!$C$5:$C$39,B18) -> 100 | D18: =IFERROR(C18/$C$4,0) -> 0.014285714 | E18: 0.1 | F18: Max | G18: =IF(E18="","—",IF(F18="Max",IF(D18<=E18,"OK - within recommended range","Above recommended - consider reducing"),IF(D18>=E18,"OK - meeting target","Below recommended - consider increasing"))) -> OK - within recommended range
B19: Other | C19: =SUMIFS('Budget Input'!$D$5:$D$39,'Budget Input'!$B$5:$B$39,"Expense",'Budget Input'!$C$5:$C$39,B19) -> 0 | D19: =IFERROR(C19/$C$4,0) -> 0 | E19: 0.02 | F19: Max | G19: =IF(E19="","—",IF(F19="Max",IF(D19<=E19,"OK - within recommended range","Above recommended - consider reducing"),IF(D19>=E19,"OK - meeting target","Below recommended - consider increasing"))) -> OK - within recommended range
B21: SUBSCRIPTIONS INSIGHT
B22: Total Monthly Subscription Cost (detail list) | C22: =+'Budget Input'!I10 -> 20.333333
B23: Estimated Annual Subscription Cost | C23: =C22*12 -> 244
B24: Active Subscriptions Count | C24: =COUNTIF('Budget Input'!F43:F67,">0") -> 3
B25: Subscriptions Feedback | C25: =IF(C24>8,"You have many active subscriptions - this is a great place to look for quick savings.",IF(C24>4,"You have a moderate number of subscriptions - worth a periodic review.","Lean subscription list - nice work.")) -> Lean subscription list - nice work.
B27: OVERALL FEEDBACK
B28: Cash Flow | C28: =IF(C6<0,"You are spending more than you earn. Consider reducing expenses or increasing income.",IF(IFERROR(C6/C4,0)<0.1,"You have a small surplus. Building a bigger buffer could help with unexpected expenses.","Healthy surplus - you are earning more than you spend each month.")) -> You have a small surplus. Building a bigger buffer could help with unexpected expenses.
B29: Investing Rate | C29: =IF(C7>=0.2,"Great! You are investing 20% or more of your income, a widely recommended target.",IF(C7>=0.1,"You are investing between 10-20% of your income. Consider increasing this over time.","You are investing less than 10% of your income. Consider prioritizing savings/investing if possible.")) -> Great! You are investing 20% or more of your income, a widely recommended target.
B31: VISUAL SUMMARY
B32: For visual learners — these update automatically as you fill in the Budget Input tab.

Sheet Lists
A1: Income | B1: Salary/Wages | D1: Yes | F1: Monthly
A2: Expense | B2: Side Income | D2: No | F2: Annual
A3: Taxes | B3: Other Income
A4: Investing | B4: Housing
B5: Transportation
B6: Food
B7: Utilities
B8: Insurance
B9: Subscriptions
B10: Personal & Discretionary
B11: Other
B12: Federal
B13: State
B14: Social Security
B15: Medicare
B16: Retirement
... B21: 401(k)

Sheet Debt Payoff
B1: Debt Payoff Planner
B3: YOUR DEBTS | L3: TOTALS
B4: Debt Name | C4: Balance | D4: APR | E4: Min Payment | F4: Extra Payment | G4: Months to Payoff | H4: Est. Interest | I4: Snowball Order | J4: Avalanche Order | L4: Total Debt Balance | M4: =SUM(C5:C9) -> 18000
B5: Auto Loan | C5: 18000 | D5: 0.04 | E5: 350 | G5: =IF(OR($C5<=0,($E5+$F5)<=0),"-",IF($D5=0,ROUNDUP($C5/($E5+$F5),0),IF(($E5+$F5)<=$C5*($D5/12),"Increase payment",ROUNDUP(-LN(1-($C5*($D5/12))/($E5+$F5))/LN(1+($D5/12)),0)))) -> 57 | H5: =IFERROR(IF(ISNUMBER(G5),ROUND((G5-1)*($E5+$F5)+IF($D5=0,$C5-($E5+$F5)*(G5-1),($C5*(1+$D5/12)^(G5-1)-($E5+$F5)*((1+$D5/12)^(G5-1)-1)/($D5/12))*(1+$D5/12))-$C5,2),"-"),"-") -> 1778.52 | I5: =IF(OR($C5="",$C5<=0),"-",RANK($C5,$C$5:$C$9,1)) -> 1 | J5: =IF(OR($D5="",$C5<=0),"-",RANK($D5,$D$5:$D$9,0)) -> 1 | L5: Total Minimum Payments | M5: =SUM(E5:E9) -> 350
G6: =IF(OR($C6<=0,($E6+$F6)<=0),"-",IF($D6=0,ROUNDUP($C6/($E6+$F6),0),IF(($E6+$F6)<=$C6*($D6/12),"Increase payment",ROUNDUP(-LN(1-($C6*($D6/12))/($E6+$F6))/LN(1+($D6/12)),0)))) -> - | H6: =IFERROR(IF(ISNUMBER(G6),ROUND((G6-1)*($E6+$F6)+IF($D6=0,$C6-($E6+$F6)*(G6-1),($C6*(1+$D6/12)^(G6-1)-($E6+$F6)*((1+$D6/12)^(G6-1)-1)/($D6/12))*(1+$D6/12))-$C6,2),"-"),"-") -> - | I6: =IF(OR($C6="",$C6<=0),"-",RANK($C6,$C$5:$C$9,1)) -> - | J6: =IF(OR($D6="",$C6<=0),"-",RANK($D6,$D$5:$D$9,0)) -> - | L6: Total Extra Payments | M6: =SUM(F5:F9) -> 0
G7: =IF(OR($C7<=0,($E7+$F7)<=0),"-",IF($D7=0,ROUNDUP($C7/($E7+$F7),0),IF(($E7+$F7)<=$C7*($D7/12),"Increase payment",ROUNDUP(-LN(1-($C7*($D7/12))/($E7+$F7))/LN(1+($D7/12)),0)))) -> - | H7: =IFERROR(IF(ISNUMBER(G7),ROUND((G7-1)*($E7+$F7)+IF($D7=0,$C7-($E7+$F7)*(G7-1),($C7*(1+$D7/12)^(G7-1)-($E7+$F7)*((1+$D7/12)^(G7-1)-1)/($D7/12))*(1+$D7/12))-$C7,2),"-"),"-") -> - | I7: =IF(OR($C7="",$C7<=0),"-",RANK($C7,$C$5:$C$9,1)) -> - | J7: =IF(OR($D7="",$C7<=0),"-",RANK($D7,$D$5:$D$9,0)) -> - | L7: Total Monthly Debt Payment | M7: =M5+M6 -> 350
G8: =IF(OR($C8<=0,($E8+$F8)<=0),"-",IF($D8=0,ROUNDUP($C8/($E8+$F8),0),IF(($E8+$F8)<=$C8*($D8/12),"Increase payment",ROUNDUP(-LN(1-($C8*($D8/12))/($E8+$F8))/LN(1+($D8/12)),0)))) -> - | H8: =IFERROR(IF(ISNUMBER(G8),ROUND((G8-1)*($E8+$F8)+IF($D8=0,$C8-($E8+$F8)*(G8-1),($C8*(1+$D8/12)^(G8-1)-($E8+$F8)*((1+$D8/12)^(G8-1)-1)/($D8/12))*(1+$D8/12))-$C8,2),"-"),"-") -> - | I8: =IF(OR($C8="",$C8<=0),"-",RANK($C8,$C$5:$C$9,1)) -> - | J8: =IF(OR($D8="",$C8<=0),"-",RANK($D8,$D$5:$D$9,0)) -> - | L8: Weighted Avg APR | M8: =IFERROR(SUMPRODUCT(C5:C9,D5:D9)/SUM(C5:C9),0) -> 0.04
G9: =IF(OR($C9<=0,($E9+$F9)<=0),"-",IF($D9=0,ROUNDUP($C9/($E9+$F9),0),IF(($E9+$F9)<=$C9*($D9/12),"Increase payment",ROUNDUP(-LN(1-($C9*($D9/12))/($E9+$F9))/LN(1+($D9/12)),0)))) -> - | H9: =IFERROR(IF(ISNUMBER(G9),ROUND((G9-1)*($E9+$F9)+IF($D9=0,$C9-($E9+$F9)*(G9-1),($C9*(1+$D9/12)^(G9-1)-($E9+$F9)*((1+$D9/12)^(G9-1)-1)/($D9/12))*(1+$D9/12))-$C9,2),"-"),"-") -> - | I9: =IF(OR($C9="",$C9<=0),"-",RANK($C9,$C$5:$C$9,1)) -> - | J9: =IF(OR($D9="",$C9<=0),"-",RANK($D9,$D$5:$D$9,0)) -> -
B11: Snowball = pay off smallest balance first (fastest wins). Avalanche = pay off highest APR first (saves the most money). Each debt is calculated independently at its own payment amount, including a reduced final payment in the payoff month so the interest total is accurate — not a full multi-debt rollover simulation.
B13: Input your numbers; such as car loans, credit card debt, and current mortgages into the yellow cells and let the sheet do the rest! Your Total Monthly Debt Payment (including any Extra Payment) flows automatically into the Budget Input tab — no manual entry needed there.

Sheet Interest Saved
B2: Interest Saved / Payoff Acceleration
B4: YOUR LOAN
B5: Select Debt to Analyze
B6: Current Balance | C6: {=IFERROR(INDEX('Debt Payoff'!$C$5:$C$9,MATCH($C$5,'Debt Payoff'!$B$5:$B$9,0)),0)} -> 0
B7: Interest Rate (APR) | C7: {=IFERROR(INDEX('Debt Payoff'!$D$5:$D$9,MATCH($C$5,'Debt Payoff'!$B$5:$B$9,0)),0)} -> 0
B8: Minimum Payment | C8: {=IFERROR(INDEX('Debt Payoff'!$E$5:$E$9,MATCH($C$5,'Debt Payoff'!$B$5:$B$9,0)),0)} -> 0
B9: Extra Monthly Payment
B11: RESULTS
B12: Months to Payoff — Minimum Only | C12: =IF(OR($C$6<=0,$C$8<=0),"-",IF($C$7=0,ROUNDUP($C$6/$C$8,0),IF($C$8<=$C$6*($C$7/12),"Increase payment",ROUNDUP(-LN(1-($C$6*($C$7/12))/$C$8)/LN(1+($C$7/12)),0)))) -> -
B13: Months to Payoff — Minimum + Extra | C13: =IF(OR($C$6<=0,($C$8+$C$9)<=0),"-",IF($C$7=0,ROUNDUP($C$6/($C$8+$C$9),0),IF(($C$8+$C$9)<=$C$6*($C$7/12),"Increase payment",ROUNDUP(-LN(1-($C$6*($C$7/12))/($C$8+$C$9))/LN(1+($C$7/12)),0)))) -> -
B14: Time Saved | C14: =IF(AND(ISNUMBER(C12),ISNUMBER(C13)),C12-C13,"-") -> -
B15: Total Interest — Minimum Only | C15: =IF(ISNUMBER(C12),ROUND((C12-1)*C8+IF(C7=0,C6-C8*(C12-1),(C6*(1+C7/12)^(C12-1)-C8*((1+C7/12)^(C12-1)-1)/(C7/12))*(1+C7/12))-C6,2),"-") -> -
B16: Total Interest — Minimum + Extra | C16: =IF(ISNUMBER(C13),ROUND((C13-1)*(C8+C9)+IF(C7=0,C6-(C8+C9)*(C13-1),(C6*(1+C7/12)^(C13-1)-(C8+C9)*((1+C7/12)^(C13-1)-1)/(C7/12))*(1+C7/12))-C6,2),"-") -> -
B17: Interest Saved | C17: =IF(AND(ISNUMBER(C15),ISNUMBER(C16)),C15-C16,"-") -> -
B18: Estimated Payoff Date — Minimum Only | C18: =IF(ISNUMBER(C12),TEXT(EDATE(TODAY(),C12),"mmm yyyy"),"-") -> -
B19: Estimated Payoff Date — Minimum + Extra | C19: =IF(ISNUMBER(C13),TEXT(EDATE(TODAY(),C13),"mmm yyyy"),"-") -> -
B21: BALANCE OVER TIME — MONTHLY THROUGH 60 MONTHS, ANNUAL AFTER
B22: =IF(AND(ISNUMBER($C$12),$C$12>60),"Year","Month") -> Month | C22: Balance — Minimum Only | D22: Balance — Minimum + Extra
B23: =IF(0<=IF(ISNUMBER($C$12),IF($C$12>60,ROUNDUP($C$12/12,0),$C$12),-1),0,"") | C23: =IF(B23="","",MAX(0,IF($C$7=0,$C$6-$C$8*(IF($C$12>60,B23*12,B23)),$C$6*(1+$C$7/12)^(IF($C$12>60,B23*12,B23))-$C$8*((1+$C$7/12)^(IF($C$12>60,B23*12,B23))-1)/($C$7/12)))) | D23: =IF(C23="","",MAX(0,IF($C$7=0,$C$6-$C$8*(IF($C$12>60,C23*12,C23)),$C$6*(1+$C$7/12)^(IF($C$12>60,C23*12,C23))-$C$8*((1+$C$7/12)^(IF($C$12>60,C23*12,C23))-1)/($C$7/12))))
B24: =IF(1<=IF(ISNUMBER($C$12),IF($C$12>60,ROUNDUP($C$12/12,0),$C$12),-1),1,"") | C24: =IF(B24="","",MAX(0,IF($C$7=0,$C$6-$C$8*(IF($C$12>60,B24*12,B24)),$C$6*(1+$C$7/12)^(IF($C$12>60,B24*12,B24))-$C$8*((1+$C$7/12)^(IF($C$12>60,B24*12,B24))-1)/($C$7/12)))) | D24: =IF(B24="","",MAX(0,IF($C$7=0,$C$6-($C$8+$C$9)*(IF($C$12>60,B24*12,B24)),$C$6*(1+$C$7/12)^(IF($C$12>60,B24*12,B24))-($C$8+$C$9)*((1+$C$7/12)^(IF($C$12>60,B24*12,B24))-1)/($C$7/12))))
B25: =IF(2<=IF(ISNUMBER($C$12),IF($C$12>60,ROUNDUP($C$12/12,0),$C$12),-1),2,"") | C25: =IF(B25="","",MAX(0,IF($C$7=0,$C$6-$C$8*(IF($C$12>60,B25*12,B25)),$C$6*(1+$C$7/12)^(IF($C$12>60,B25*12,B25))-$C$8*((1+$C$7/12)^(IF($C$12>60,B25*12,B25))-1)/($C$7/12)))) | D25: =IF(B25="","",MAX(0,IF($C$7=0,$C$6-($C$8+$C$9)*(IF($C$12>60,B25*12,B25)),$C$6*(1+$C$7/12)^(IF($C$12>60,B25*12,B25))-($C$8+$C$9)*((1+$C$7/12)^(IF($C$12>60,B25*12,B25))-1)/($C$7/12))))
B26: =IF(3<=IF(ISNUMBER($C$12),IF($C$12>60,ROUNDUP($C$12/12,0),$C$12),-1),3,"") | C26: =IF(B26="","",MAX(0,IF($C$7=0,$C$6-$C$8*(IF($C$12>60,B26*12,B26)),$C$6*(1+$C$7/12)^(IF($C$12>60,B26*12,B26))-$C$8*((1+$C$7/12)^(IF($C$12>60,B26*12,B26))-1)/($C$7/12)))) | D26: =IF(B26="","",MAX(0,IF($C$7=0,$C$6-($C$8+$C$9)*(IF($C$12>60,B26*12,B26)),$C$6*(1+$C$7/12)^(IF($C$12>60,B26*12,B26))-($C$8+$C$9)*((1+$C$7/12)^(IF($C$12>60,B26*12,B26))-1)/($C$7/12))))
B27: =IF(4<=IF(ISNUMBER($C$12),IF($C$12>60,ROUNDUP($C$12/12,0),$C$12),-1),4,"") | C27: =IF(B27="","",MAX(0,IF($C$7=0,$C$6-$C$8*(IF($C$12>60,B27*12,B27)),$C$6*(1+$C$7/12)^(IF($C$12>60,B27*12,B27))-$C$8*((1+$C$7/12)^(IF($C$12>60,B27*12,B27))-1)/($C$7/12)))) | D27: =IF(B27="","",MAX(0,IF($C$7=0,$C$6-($C$8+$C$9)*(IF($C$12>60,B27*12,B27)),$C$6*(1+$C$7/12)^(IF($C$12>60,B27*12,B27))-($C$8+$C$9)*((1+$C$7/12)^(IF($C$12>60,B27*12,B27))-1)/($C$7/12))))
B28: =IF(5<=IF(ISNUMBER($C$12),IF($C$12>60,ROUNDUP($C$12/12,0),$C$12),-1),5,"") | C28: =IF(B28="","",MAX(0,IF($C$7=0,$C$6-$C$8*(IF($C$12>60,B28*12,B28)),$C$6*(1+$C$7/12)^(IF($C$12>60,B28*12,B28))-$C$8*((1+$C$7/12)^(IF($C$12>60,B28*12,B28))-1)/($C$7/12)))) | D28: =IF(B28="","",MAX(0,IF($C$7=0,$C$6-($C$8+$C$9)*(IF($C$12>60,B28*12,B28)),$C$6*(1+$C$7/12)^(IF($C$12>60,B28*12,B28))-($C$8+$C$9)*((1+$C$7/12)^(IF($C$12>60,B28*12,B28))-1)/($C$7/12))))
B29: =IF(6<=IF(ISNUMBER($C$12),IF($C$12>60,ROUNDUP($C$12/12,0),$C$12),-1),6,"") | C29: =IF(B29="","",MAX(0,IF($C$7=0,$C$6-$C$8*(IF($C$12>60,B29*12,B29)),$C$6*(1+$C$7/12)^(IF($C$12>60,B29*12,B29))-$C$8*((1+$C$7/12)^(IF($C$12>60,B29*12,B29))-1)/($C$7/12)))) | D29: =IF(B29="","",MAX(0,IF($C$7=0,$C$6-($C$8+$C$9)*(IF($C$12>60,B29*12,B29)),$C$6*(1+$C$7/12)^(IF($C$12>60,B29*12,B29))-($C$8+$C$9)*((1+$C$7/12)^(IF($C$12>60,B29*12,B29))-1)/($C$7/12))))
B30: =IF(7<=IF(ISNUMBER($C$12),IF($C$12>60,ROUNDUP($C$12/12,0),$C$12),-1),7,"") | C30: =IF(B30="","",MAX(0,IF($C$7=0,$C$6-$C$8*(IF($C$12>60,B30*12,B30)),$C$6*(1+$C$7/12)^(IF($C$12>60,B30*12,B30))-$C$8*((1+$C$7/12)^(IF($C$12>60,B30*12,B30))-1)/($C$7/12)))) | D30: =IF(B30="","",MAX(0,IF($C$7=0,$C$6-($C$8+$C$9)*(IF($C$12>60,B30*12,B30)),$C$6*(1+$C$7/12)^(IF($C$12>60,B30*12,B30))-($C$8+$C$9)*((1+$C$7/12)^(IF($C$12>60,B30*12,B30))-1)/($C$7/12))))
B31: =IF(8<=IF(ISNUMBER($C$12),IF($C$12>60,ROUNDUP($C$12/12,0),$C$12),-1),8,"") | C31: =IF(B31="","",MAX(0,IF($C$7=0,$C$6-$C$8*(IF($C$12>60,B31*12,B31)),$C$6*(1+$C$7/12)^(IF($C$12>60,B31*12,B31))-$C$8*((1+$C$7/12)^(IF($C$12>60,B31*12,B31))-1)/($C$7/12)))) | D31: =IF(B31="","",MAX(0,IF($C$7=0,$C$6-($C$8+$C$9)*(IF($C$12>60,B31*12,B31)),$C$6*(1+$C$7/12)^(IF($C$12>60,B31*12,B31))-($C$8+$C$9)*((1+$C$7/12)^(IF($C$12>60,B31*12,B31))-1)/($C$7/12))))
B32: =IF(9<=IF(ISNUMBER($C$12),IF($C$12>60,ROUNDUP($C$12/12,0),$C$12),-1),9,"") | C32: =IF(B32="","",MAX(0,IF($C$7=0,$C$6-$C$8*(IF($C$12>60,B32*12,B32)),$C$6*(1+$C$7/12)^(IF($C$12>60,B32*12,B32))-$C$8*((1+$C$7/12)^(IF($C$12>60,B32*12,B32))-1)/($C$7/12)))) | D32: =IF(B32="","",MAX(0,IF($C$7=0,$C$6-($C$8+$C$9)*(IF($C$12>60,B32*12,B32)),$C$6*(1+$C$7/12)^(IF($C$12>60,B32*12,B32))-($C$8+$C$9)*((1+$C$7/12)^(IF($C$12>60,B32*12,B32))-1)/($C$7/12))))
B33: =IF(10<=IF(ISNUMBER($C$12),IF($C$12>60,ROUNDUP($C$12/12,0),$C$12),-1),10,"") | C33: =IF(B33="","",MAX(0,IF($C$7=0,$C$6-$C$8*(IF($C$12>60,B33*12,B33)),$C$6*(1+$C$7/12)^(IF($C$12>60,B33*12,B33))-$C$8*((1+$C$7/12)^(IF($C$12>60,B33*12,B33))-1)/($C$7/12)))) | D33: =IF(B33="","",MAX(0,IF($C$7=0,$C$6-($C$8+$C$9)*(IF($C$12>60,B33*12,B33)),$C$6*(1+$C$7/12)^(IF($C$12>60,B33*12,B33))-($C$8+$C$9)*((1+$C$7/12)^(IF($C$12>60,B33*12,B33))-1)/($C$7/12))))
B34: =IF(11<=IF(ISNUMBER($C$12),IF($C$12>60,ROUNDUP($C$12/12,0),$C$12),-1),11,"") | C34: =IF(B34="","",MAX(0,IF($C$7=0,$C$6-$C$8*(IF($C$12>60,B34*12,B34)),$C$6*(1+$C$7/12)^(IF($C$12>60,B34*12,B34))-$C$8*((1+$C$7/12)^(IF($C$12>60,B34*12,B34))-1)/($C$7/12)))) | D34: =IF(B34="","",MAX(0,IF($C$7=0,$C$6-($C$8+$C$9)*(IF($C$12>60,B34*12,B34)),$C$6*(1+$C$7/12)^(IF($C$12>60,B34*12,B34))-($C$8+$C$9)*((1+$C$7/12)^(IF($C$12>60,B34*12,B34))-1)/($C$7/12))))
B35: =IF(12<=IF(ISNUMBER($C$12),IF($C$12>60,ROUNDUP($C$12/12,0),$C$12),-1),12,"") | C35: =IF(B35="","",MAX(0,IF($C$7=0,$C$6-$C$8*(IF($C$12>60,B35*12,B35)),$C$6*(1+$C$7/12)^(IF($C$12>60,B35*12,B35))-$C$8*((1+$C$7/12)^(IF($C$12>60,B35*12,B35))-1)/($C$7/12)))) | D35: =IF(B35="","",MAX(0,IF($C$7=0,$C$6-($C$8+$C$9)*(IF($C$12>60,B35*12,B35)),$C$6*(1+$C$7/12)^(IF($C$12>60,B35*12,B35))-($C$8+$C$9)*((1+$C$7/12)^(IF($C$12>60,B35*12,B35))-1)/($C$7/12))))
B36: =IF(13<=IF(ISNUMBER($C$12),IF($C$12>60,ROUNDUP($C$12/12,0),$C$12),-1),13,"") | C36: =IF(B36="","",MAX(0,IF($C$7=0,$C$6-$C$8*(IF($C$12>60,B36*12,B36)),$C$6*(1+$C$7/12)^(IF($C$12>60,B36*12,B36))-$C$8*((1+$C$7/12)^(IF($C$12>60,B36*12,B36))-1)/($C$7/12)))) | D36: =IF(B36="","",MAX(0,IF($C$7=0,$C$6-($C$8+$C$9)*(IF($C$12>60,B36*12,B36)),$C$6*(1+$C$7/12)^(IF($C$12>60,B36*12,B36))-($C$8+$C$9)*((1+$C$7/12)^(IF($C$12>60,B36*12,B36))-1)/($C$7/12))))
B37: =IF(14<=IF(ISNUMBER($C$12),IF($C$12>60,ROUNDUP($C$12/12,0),$C$12),-1),14,"") | C37: =IF(B37="","",MAX(0,IF($C$7=0,$C$6-$C$8*(IF($C$12>60,B37*12,B37)),$C$6*(1+$C$7/12)^(IF($C$12>60,B37*12,B37))-$C$8*((1+$C$7/12)^(IF($C$12>60,B37*12,B37))-1)/($C$7/12)))) | D37: =IF(B37="","",MAX(0,IF($C$7=0,$C$6-($C$8+$C$9)*(IF($C$12>60,B37*12,B37)),$C$6*(1+$C$7/12)^(IF($C$12>60,B37*12,B37))-($C$8+$C$9)*((1+$C$7/12)^(IF($C$12>60,B37*12,B37))-1)/($C$7/12))))
B38: =IF(15<=IF(ISNUMBER($C$12),IF($C$12>60,ROUNDUP($C$12/12,0),$C$12),-1),15,"") | C38: =IF(B38="","",MAX(0,IF($C$7=0,$C$6-$C$8*(IF($C$12>60,B38*12,B38)),$C$6*(1+$C$7/12)^(IF($C$12>60,B38*12,B38))-$C$8*((1+$C$7/12)^(IF($C$12>60,B38*12,B38))-1)/($C$7/12)))) | D38: =IF(B38="","",MAX(0,IF($C$7=0,$C$6-($C$8+$C$9)*(IF($C$12>60,B38*12,B38)),$C$6*(1+$C$7/12)^(IF($C$12>60,B38*12,B38))-($C$8+$C$9)*((1+$C$7/12)^(IF($C$12>60,B38*12,B38))-1)/($C$7/12))))
B39: =IF(16<=IF(ISNUMBER($C$12),IF($C$12>60,ROUNDUP($C$12/12,0),$C$12),-1),16,"") | C39: =IF(B39="","",MAX(0,IF($C$7=0,$C$6-$C$8*(IF($C$12>60,B39*12,B39)),$C$6*(1+$C$7/12)^(IF($C$12>60,B39*12,B39))-$C$8*((1+$C$7/12)^(IF($C$12>60,B39*12,B39))-1)/($C$7/12)))) | D39: =IF(B39="","",MAX(0,IF($C$7=0,$C$6-($C$8+$C$9)*(IF($C$12>60,B39*12,B39)),$C$6*(1+$C$7/12)^(IF($C$12>60,B39*12,B39))-($C$8+$C$9)*((1+$C$7/12)^(IF($C$12>60,B39*12,B39))-1)/($C$7/12))))
B40: =IF(17<=IF(ISNUMBER($C$12),IF($C$12>60,ROUNDUP($C$12/12,0),$C$12),-1),17,"") | C40: =IF(B40="","",MAX(0,IF($C$7=0,$C$6-$C$8*(IF($C$12>60,B40*12,B40)),$C$6*(1+$C$7/12)^(IF($C$12>60,B40*12,B40))-$C$8*((1+$C$7/12)^(IF($C$12>60,B40*12,B40))-1)/($C$7/12)))) | D40: =IF(B40="","",MAX(0,IF($C$7=0,$C$6-($C$8+$C$9)*(IF($C$12>60,B40*12,B40)),$C$6*(1+$C$7/12)^(IF($C$12>60,B40*12,B40))-($C$8+$C$9)*((1+$C$7/12)^(IF($C$12>60,B40*12,B40))-1)/($C$7/12))))
B41: =IF(18<=IF(ISNUMBER($C$12),IF($C$12>60,ROUNDUP($C$12/12,0),$C$12),-1),18,"") | C41: =IF(B41="","",MAX(0,IF($C$7=0,$C$6-$C$8*(IF($C$12>60,B41*12,B41)),$C$6*(1+$C$7/12)^(IF($C$12>60,B41*12,B41))-$C$8*((1+$C$7/12)^(IF($C$12>60,B41*12,B41))-1)/($C$7/12)))) | D41: =IF(B41="","",MAX(0,IF($C$7=0,$C$6-($C$8+$C$9)*(IF($C$12>60,B41*12,B41)),$C$6*(1+$C$7/12)^(IF($C$12>60,B41*12,B41))-($C$8+$C$9)*((1+$C$7/12)^(IF($C$12>60,B41*12,B41))-1)/($C$7/12))))
B42: =IF(19<=IF(ISNUMBER($C$12),IF($C$12>60,ROUNDUP($C$12/12,0),$C$12),-1),19,"") | C42: =IF(B42="","",MAX(0,IF($C$7=0,$C$6-$C$8*(IF($C$12>60,B42*12,B42)),$C$6*(1+$C$7/12)^(IF($C$12>60,B42*12,B42))-$C$8*((1+$C$7/12)^(IF($C$12>60,B42*12,B42))-1)/($C$7/12)))) | D42: =IF(B42="","",MAX(0,IF($C$7=0,$C$6-($C$8+$C$9)*(IF($C$12>60,B42*12,B42)),$C$6*(1+$C$7/12)^(IF($C$12>60,B42*12,B42))-($C$8+$C$9)*((1+$C$7/12)^(IF($C$12>60,B42*12,B42))-1)/($C$7/12))))
B43: =IF(20<=IF(ISNUMBER($C$12),IF($C$12>60,ROUNDUP($C$12/12,0),$C$12),-1),20,"") | C43: =IF(B43="","",MAX(0,IF($C$7=0,$C$6-$C$8*(IF($C$12>60,B43*12,B43)),$C$6*(1+$C$7/12)^(IF($C$12>60,B43*12,B43))-$C$8*((1+$C$7/12)^(IF($C$12>60,B43*12,B43))-1)/($C$7/12)))) | D43: =IF(B43="","",MAX(0,IF($C$7=0,$C$6-($C$8+$C$9)*(IF($C$12>60,B43*12,B43)),$C$6*(1+$C$7/12)^(IF($C$12>60,B43*12,B43))-($C$8+$C$9)*((1+$C$7/12)^(IF($C$12>60,B43*12,B43))-1)/($C$7/12))))
B44: =IF(21<=IF(ISNUMBER($C$12),IF($C$12>60,ROUNDUP($C$12/12,0),$C$12),-1),21,"") | C44: =IF(B44="","",MAX(0,IF($C$7=0,$C$6-$C$8*(IF($C$12>60,B44*12,B44)),$C$6*(1+$C$7/12)^(IF($C$12>60,B44*12,B44))-$C$8*((1+$C$7/12)^(IF($C$12>60,B44*12,B44))-1)/($C$7/12)))) | D44: =IF(B44="","",MAX(0,IF($C$7=0,$C$6-($C$8+$C$9)*(IF($C$12>60,B44*12,B44)),$C$6*(1+$C$7/12)^(IF($C$12>60,B44*12,B44))-($C$8+$C$9)*((1+$C$7/12)^(IF($C$12>60,B44*12,B44))-1)/($C$7/12))))
...

Sheet Net Worth
B1: Net Worth Tracker
B3: ASSETS
B4: Item | C4: Amount
B5: Cash & Checking | C5: 10000
B6: Savings | C6: 10000
B7: Investments (Brokerage / Retirement) | C7: 100000
B8: Home / Property Value | C8: 0
B9: Vehicles | C9: 15000
B10: Other | C10: 2000
B11: Total Assets | C11: =SUM(C5:C10) -> 137000
B13: LIABILITIES
B14: Item | C14: Amount
B15: Mortgage Balance | C15: 0
B16: Total Debt (pulled from Debt Payoff tab) | C16: ='Debt Payoff'!M4 -> 18000
B17: Other Liabilities | C17: 0
B19: Total Liabilities | C19: =SUM(C15:C17) -> 18000
B21: NET WORTH
B22: Net Worth (Assets − Liabilities) | C22: =C11-C19 -> 119000
B24: Tip: update this tab monthly, then copy the Net Worth figure into the Annual Review (History & Trends) tab to build your trend line over time.

Sheet Emergency Fund
B1: Emergency Fund Tracker
B3: YOUR NUMBERS
B4: Monthly Essential Expenses | C4: {=SUMPRODUCT(('Budget Input'!$B$5:$B$39="Expense")*(ISNUMBER(MATCH('Budget Input'!$C$5:$C$39,{"Housing";"Transportation";"Food";"Utilities";"Insurance"},0)))*('Budget Input'!$D$5:$D$39))+'Debt Payoff'!$M$5} -> 3500
B5: Target Months of Coverage | C5: 6
B6: Current Emergency Fund Balance (pulled from Net Worth Tab) | C6: ='Net Worth'!C6 -> 10000
B8: RESULTS
B9: Target Amount | C9: =C4*C5 -> 21000
B10: Progress | C10: =IFERROR(MIN(C6/C9,1),0) -> 0.47619048
B11: Months Currently Covered | C11: =IFERROR(C6/C4,0) -> 2.8571429
B12: Feedback | C12: =IF(C10>=1,"Fully funded — nice work. Consider directing extra cash to debt or investing instead.",IF(C10>=0.5,"Over halfway there. Keep the momentum going.","Just getting started — even $25/month builds real momentum here.")) -> Just getting started — even $25/month builds real momentum here.
B14: GOAL TIMELINE
B15: Monthly Contribution Toward Goal | C15: 300
B16: Months to Reach Goal (at this contribution) | C16: =IF(C6>=C9,0,IF(C15<=0,"Enter a monthly amount above",ROUNDUP((C9-C6)/C15,0))) -> 37
B17: Estimated Date to Reach Goal | C17: =IF(C6>=C9,"Goal already reached",IF(ISNUMBER(C16),TEXT(EDATE(TODAY(),C16),"mmm yyyy"),"-")) -> Sep 2029
B19: Tip: to update this tab, simply input your desired number of months to be covered for (Target Months of Coverage) and how much you desire to contribute each month! The other numbers are automatically calculated. Realize that you will need to add your desired contributions to the Budget Input tab under investing! Your minimum required debt payments (from the Debt Payoff tab) are already included in your essential expenses above.

Sheet Mortgage Estimator
B1: Home Affordability & Mortgage Estimator
B3: YOUR FINANCES | E3: ESTIMATE A SPECIFIC HOME
B4: Annual Gross Income | C4: ='Budget Input'!I5*12 -> 84000 | E4: Home Price to Evaluate
B5: Required Monthly Debt Payments (minimums) | C5: ='Debt Payoff'!M5 -> 350 | E5: Loan Amount (Price − Down Payment) | F5: =MAX(0,F4-C6) -> 0
B6: Down Payment Available | E6: Monthly Principal & Interest | F6: =IF(F5<=0,0,IF(C11=0,F5/(C12*12),F5*(C11/12)/(1-(1+C11/12)^(-C12*12)))) -> 0
B7: Target Front-End DTI (housing ÷ income) | C7: 0.28 | E7: Monthly Property Tax | F7: =F4*C13/12 -> 0
B8: Target Back-End DTI (all debt ÷ income) | C8: 0.36 | E8: Monthly Home Insurance | F8: =C14/12 -> 125
E9: Monthly HOA | F9: =C15 -> 0
B10: LOAN ASSUMPTIONS | E10: Total Monthly Payment (PITI) | F10: =SUM(F6:F9) -> 125
B11: Interest Rate (APR) | C11: 0.065 | E11: Resulting Front-End DTI | F11: =IFERROR(F10/(C4/12),0) -> 0.017857143
B12: Loan Term (years) | C12: 30 | E12: Resulting Back-End DTI | F12: =IFERROR((F10+C5)/(C4/12),0) -> 0.067857143
B13: Property Tax Rate (annual, % of home value) | C13: 0.011 | E13: Affordability Verdict | F13: =IF(OR(F4="",F4=0),"Enter a home price above",IF(AND(F11<=C7,F12<=C8),"Within your guidelines","Above your target guidelines")) -> Enter a home price above
B14: Annual Home Insurance | C14: 1500
B15: Monthly HOA | C15: 0 | E15: Property tax and insurance are estimates based on the rate and amount you entered above — actual costs vary by lender, county, and homeowner's insurance carrier. This is educational, not a loan pre-approval.
B17: WHAT YOU CAN AFFORD
B18: Max Monthly Payment — Front-End (28% rule) | C18: =(C4/12)*C7 -> 1960 | E18: DTI BENCHMARKS — WHAT LENDERS LOOK FOR
B19: Max Monthly Payment — Back-End (36% rule) | C19: =MAX(0,(C4/12)*C8-C5) -> 2170 | E19: Debt-to-income (DTI) is the share of your gross monthly income that goes toward debt. Lenders use two versions — front-end (housing only) and back-end (all debt). Lower is safer; higher limits your loan options.
B20: Max Total Housing Payment (lower of the two) | C20: =MIN(C18,C19) -> 1960
E21: Front-End DTI (housing ÷ income)
B22: THE MATH BEHIND IT (click + to expand) | E22: ≤ 28% | F22: Ideal — the classic conventional-loan sweet spot
B23: Step 1 — Est. Principal & Interest (before tax) | C23: =MAX(0,C20-C14/12-C15) -> 1835 | E23: 28% – 31% | F23: Acceptable to most lenders
B24: Step 1 — Implied Loan Amount | C24: =IF(C11=0,C23*C12*12,C23*(1-(1+C11/12)^(-C12*12))/(C11/12)) -> 290316.85 | E24: > 31% | F24: May need strong credit or a larger down payment
B25: Step 1 — Implied Home Value | C25: =C24+C6 -> 290316.85 | E25: Back-End DTI (all debt ÷ income)
B26: Step 1 — Est. Monthly Property Tax | C26: =C25*C13/12 -> 266.12378 | E26: ≤ 36% | F26: Ideal — standard conventional guideline
B27: Step 2 — Refined Principal & Interest | C27: =MAX(0,C20-C26-C14/12-C15) -> 1568.8762 | E27: 36% – 43% | F27: Upper limit for many conventional loans
E28: 43% – 50% | F28: FHA/other programs only, with strong credit
B29: BOTTOM LINE — WHAT YOU CAN AFFORD | E29: > 50% | F29: Approval unlikely with most lenders
B30: Max Loan Amount | C30: =IF(C11=0,C27*C12*12,C27*(1-(1+C11/12)^(-C12*12))/(C11/12)) -> 248213.19 | E30: This tool defaults to the classic 28% / 36% rule (cells C7 and C8, left). Adjust those two cells if your lender uses different limits.
B31: Max Home Price | C31: =C30+C6 -> 248213.19
B32: Est. Total Monthly Payment (PITI) | C32: =C27+C26+C14/12+C15 -> 1960
B34: IN PLAIN ENGLISH
B35: ="Based on your income, debts, and down payment, you could likely afford a home up to "&TEXT(C31,"$#,##0")&", with a total monthly payment (principal, interest, taxes, and insurance) around "&TEXT(C32,"$#,##0")&" per month." -> Based on your income, debts, and down payment, you could likely afford a home up to $248,213, with a total monthly payment (principal, interest, taxes, and insurance) around $1,960 per month.

Sheet Annual Review
B1: History & Trends | J1: Investment Goal Projection
B3: MONTHLY LOG | J3: YOUR ASSUMPTIONS | M3: YOUR OUTLOOK
B4: Month | C4: Income | D4: Expenses | E4: Surplus | F4: Net Worth | G4: Notes | J4: Current invested balance | K4: 126000 | M4: Years to goal | N4: =IF(K4>=K7,0,IF(AND(K5<=0,K6<=0),NA(),IF(K6=0,(K7-K4)/K5,NPER(K6,-K5,-K4,K7)))) -> 28.335054
B5: Jan | C5: 7000 | D5: 3700 | E5: =IF(OR(C5="",D5=""),"",C5-D5) -> 3300 | F5: 119000 | J5: Annual contribution | K5: 19200 | M5: Estimated goal year | N5: =IFERROR(K8+ROUNDUP(N4,0),"—") -> 2052
B6: Feb | C6: 7000 | D6: 3700 | E6: =IF(OR(C6="",D6=""),"",C6-D6) -> 3300 | F6: 123000 | J6: Expected annual return | K6: 0.08 | M6: Balance in 10 years | N6: =IF(K6=0,K4+K5*10,K4*(1+K6)^10+K5*((1+K6)^10-1)/K6) -> 550166.55
B7: Mar | C7: 7000 | D7: 3700 | E7: =IF(OR(C7="",D7=""),"",C7-D7) -> 3300 | F7: 126000 | J7: Target portfolio | K7: 3000000 | M7: Total contributed at goal | N7: =IFERROR(K4+K5*ROUNDUP(N4,0),"—") -> 682800
B8: Apr | E8: =IF(OR(C8="",D8=""),"",C8-D8) | J8: Projection start year | K8: 2023 | M8: Estimated investment growth | N8: =IFERROR(K7-N7,"—") -> 2317200
B9: May | E9: =IF(OR(C9="",D9=""),"",C9-D9)
B10: Jun | E10: =IF(OR(C10="",D10=""),"",C10-D10) | J10: This is an educational projection, not a guarantee. Returns vary, inflation reduces future purchasing power, and taxes/fees are not modeled. Adjust the assumptions to explore scenarios.
B11: Jul | E11: =IF(OR(C11="",D11=""),"",C11-D11)
B12: Aug | E12: =IF(OR(C12="",D12=""),"",C12-D12)
B13: Sep | E13: =IF(OR(C13="",D13=""),"",C13-D13)
B14: Oct | E14: =IF(OR(C14="",D14=""),"",C14-D14)
B15: Nov | E15: =IF(OR(C15="",D15=""),"",C15-D15)
B16: Dec | E16: =IF(OR(C16="",D16=""),"",C16-D16)
B18: Fill in Income and Expenses from your Budget Input tab each month, and Net Worth from the Net Worth tab, to build a real trend line over time.
J42: Year | K42: Contributions | L42: Projected Balance | M42: Goal
J43: =$K$8+0 -> 2023 | K43: =$K$4+$K$5*0 -> 126000 | L43: =$K$4 -> 126000 | M43: =$K$7 -> 3000000
J44: =$K$8+1 -> 2024 | K44: =$K$4+$K$5*1 -> 145200 | L44: =L43*(1+$K$6)+$K$5 -> 155280 | M44: =$K$7 -> 3000000
J45: =$K$8+2 -> 2025 | K45: =$K$4+$K$5*2 -> 164400 | L45: =L44*(1+$K$6)+$K$5 -> 186902.4 | M45: =$K$7 -> 3000000
J46: =$K$8+3 -> 2026 | K46: =$K$4+$K$5*3 -> 183600 | L46: =L45*(1+$K$6)+$K$5 -> 221054.59 | M46: =$K$7 -> 3000000
J47: =$K$8+4 -> 2027 | K47: =$K$4+$K$5*4 -> 202800 | L47: =L46*(1+$K$6)+$K$5 -> 257938.96 | M47: =$K$7 -> 3000000
J48: =$K$8+5 -> 2028 | K48: =$K$4+$K$5*5 -> 222000 | L48: =L47*(1+$K$6)+$K$5 -> 297774.08 | M48: =$K$7 -> 3000000
J49: =$K$8+6 -> 2029 | K49: =$K$4+$K$5*6 -> 241200 | L49: =L48*(1+$K$6)+$K$5 -> 340796 | M49: =$K$7 -> 3000000
J50: =$K$8+7 -> 2030 | K50: =$K$4+$K$5*7 -> 260400 | L50: =L49*(1+$K$6)+$K$5 -> 387259.68 | M50: =$K$7 -> 3000000
J51: =$K$8+8 -> 2031 | K51: =$K$4+$K$5*8 -> 279600 | L51: =L50*(1+$K$6)+$K$5 -> 437440.46 | M51: =$K$7 -> 3000000
J52: =$K$8+9 -> 2032 | K52: =$K$4+$K$5*9 -> 298800 | L52: =L51*(1+$K$6)+$K$5 -> 491635.69 | M52: =$K$7 -> 3000000
J53: =$K$8+10 -> 2033 | K53: =$K$4+$K$5*10 -> 318000 | L53: =L52*(1+$K$6)+$K$5 -> 550166.55 | M53: =$K$7 -> 3000000
J54: =$K$8+11 -> 2034 | K54: =$K$4+$K$5*11 -> 337200 | L54: =L53*(1+$K$6)+$K$5 -> 613379.87 | M54: =$K$7 -> 3000000
J55: =$K$8+12 -> 2035 | K55: =$K$4+$K$5*12 -> 356400 | L55: =L54*(1+$K$6)+$K$5 -> 681650.26 | M55: =$K$7 -> 3000000
J56: =$K$8+13 -> 2036 | K56: =$K$4+$K$5*13 -> 375600 | L56: =L55*(1+$K$6)+$K$5 -> 755382.28 | M56: =$K$7 -> 3000000
J57: =$K$8+14 -> 2037 | K57: =$K$4+$K$5*14 -> 394800 | L57: =L56*(1+$K$6)+$K$5 -> 835012.87 | M57: =$K$7 -> 3000000
J58: =$K$8+15 -> 2038 | K58: =$K$4+$K$5*15 -> 414000 | L58: =L57*(1+$K$6)+$K$5 -> 921013.9 | M58: =$K$7 -> 3000000
J59: =$K$8+16 -> 2039 | K59: =$K$4+$K$5*16 -> 433200 | L59: =L58*(1+$K$6)+$K$5 -> 1013895 | M59: =$K$7 -> 3000000
J60: =$K$8+17 -> 2040 | K60: =$K$4+$K$5*17 -> 452400 | L60: =L59*(1+$K$6)+$K$5 -> 1114206.6 | M60: =$K$7 -> 3000000
J61: =$K$8+18 -> 2041 | K61: =$K$4+$K$5*18 -> 471600 | L61: =L60*(1+$K$6)+$K$5 -> 1222543.1 | M61: =$K$7 -> 3000000
J62: =$K$8+19 -> 2042 | K62: =$K$4+$K$5*19 -> 490800 | L62: =L61*(1+$K$6)+$K$5 -> 1339546.6 | M62: =$K$7 -> 3000000
J63: =$K$8+20 -> 2043 | K63: =$K$4+$K$5*20 -> 510000 | L63: =L62*(1+$K$6)+$K$5 -> 1465910.3 | M63: =$K$7 -> 3000000
J64: =$K$8+21 -> 2044 | K64: =$K$4+$K$5*21 -> 529200 | L64: =L63*(1+$K$6)+$K$5 -> 1602383.1 | M64: =$K$7 -> 3000000
J65: =$K$8+22 -> 2045 | K65: =$K$4+$K$5*22 -> 548400 | L65: =L64*(1+$K$6)+$K$5 -> 1749773.8 | M65: =$K$7 -> 3000000
...

Sheet License
A1: IN THE BLACK BUDGET
A2: Premium Toolkit — License & Terms of Use
A4: Product: | B4: In The Black Premium Toolkit
A5: Version: | B5: 1.0
A6: License Type: | B6: Personal Use
A7: License ID: | B7: ITB-XXXXXXXX
A8: Licensed To: | B8: Customer Name / Email
A11: Terms of Use
A12: 1. License Grant | B12: These Legal Terms constitute a legally binding agreement made between you, whether personally or on behalf of any entity, and In The Black Budget LLC. You agree that by accessing the Services, you have read, understood, and agreed to be bound by all of these Legal Terms. Subject to payment and compliance with these terms, the purchaser receives a limited, non-exclusive, non-transferable license to use one licensed copy of the In The Black Premium Toolkit for the purchaser's own personal, non-commercial financial planning and budgeting purposes.
A13: 2. Ownership | B13: The workbook, including its original content, structure, design, formulas, calculations, graphics, instructions, and other original materials, is owned by or licensed to In The Black Budget LLC and is protected by applicable intellectual-property laws. Purchase of the workbook does not transfer ownership of the underlying intellectual property to the purchaser.
A14: 3. Restrictions | B14: Except as expressly permitted by In The Black in writing, the purchaser may not sell, resell, sublicense, assign, transfer, publish, upload, distribute, share, reproduce, or otherwise make the workbook or a substantial portion of it available to another person or the public. The purchaser may not use the workbook to create or distribute a competing commercial product.
A15: 4. Personal Use | B15: The license is intended for the individual purchaser's personal use. A separate license should be obtained for another individual, household arrangement, business, employer, client, or other commercial use where applicable.
A16: 5. License Identification | B16: Each distributed copy contains a unique License ID and other identifying information associated with the purchaser. This information may be used for license administration, customer support, fraud prevention, and investigation of unauthorized redistribution.
A17: 6. Updates and Support | B17: Updates, revisions, support, and other services, if offered, may be subject to separate terms and may depend on the purchaser maintaining a valid license.
A18: 7. Disclaimer | B18: The workbook is an educational and organizational tool and is not a substitute for individualized financial, tax, legal, investment, lending, or other professional advice. Users are responsible for evaluating information and decisions applicable to their circumstances.
A19: 8. Unauthorized Distribution | B19: Unauthorized distribution or commercial use may result in suspension or termination of the license and may lead to enforcement of applicable contractual and intellectual-property rights.
A20: 9. Acceptance | B20: By purchasing, downloading, accessing, or using the workbook, the user acknowledges that the workbook is licensed rather than sold as an assignment of intellectual-property ownership and agrees to comply with the applicable Terms of Use presented at the time of purchase.
A22: Copyright Notice | B22: © 2026 In The Black. All rights reserved. This workbook is a licensed digital product.
